Traceback (most recent call last):
  File "/home/hidde/anaconda3/lib/python3.7/site-packages/jupyter_cache/executors/utils.py", line 56, in single_nb_execution
    record_timing=False,
  File "/home/hidde/anaconda3/lib/python3.7/site-packages/nbclient/client.py", line 1112, in execute
    return NotebookClient(nb=nb, resources=resources, km=km, **kwargs).execute()
  File "/home/hidde/anaconda3/lib/python3.7/site-packages/nbclient/util.py", line 74, in wrapped
    return just_run(coro(*args, **kwargs))
  File "/home/hidde/anaconda3/lib/python3.7/site-packages/nbclient/util.py", line 53, in just_run
    return loop.run_until_complete(coro)
  File "/home/hidde/anaconda3/lib/python3.7/asyncio/base_events.py", line 587, in run_until_complete
    return future.result()
  File "/home/hidde/anaconda3/lib/python3.7/site-packages/nbclient/client.py", line 554, in async_execute
    cell, index, execution_count=self.code_cells_executed + 1
  File "/home/hidde/anaconda3/lib/python3.7/site-packages/nbclient/client.py", line 857, in async_execute_cell
    self._check_raise_for_error(cell, exec_reply)
  File "/home/hidde/anaconda3/lib/python3.7/site-packages/nbclient/client.py", line 760, in _check_raise_for_error
    raise CellExecutionError.from_cell_and_msg(cell, exec_reply_content)
nbclient.exceptions.CellExecutionError: An error occurred while executing the following cell:
------------------
layer_1 = [i for i in range(7)] + [14 + i for i in range(14)]
layer_2 = [7 + i for i in range(7)] + [28 + i for i in range(14)]
orb_args = dict(args_1=[dict(l=2, m_l=2), dict(l=2, m_l=1), dict(l=2, m_l=0), dict(l=1), dict(l=0)])
elem_args = dict(args_2=[dict(atoms=layer, m_s=m_s) for layer in [layer_1, layer_2] for m_s in [-0.5, 0.5]])
legend_tags = ['layer '+str(i)+' '+Ïƒ for i in [1, 2] for Ïƒ in ['â†“', 'â†‘']]
tb.plot_wfc(
    dis_min=-5.5,
    dis_max= -3, 
    k_tags=['Î“', 'M', 'K', 'Î“'], 
    k_list=[np.array([0, 0]), np.array([4*np.pi/3, 0]), np.array([np.pi, np.pi/np.sqrt(3)]), np.zeros(2)], 
    N_k=[40, 20, 40], 
    cut=-4, 
    legend=dict(args=elem_args, tags=legend_tags, auto_color=True, auto_symbol=True), 
    slider=dict(
        args=orb_args, 
        tags=['d_xy/d_x2y2', 'dxz/dyz', 'dz2', 'p', 's'], 
        prefix='orbital'), 
    size=40)
------------------

[0;31m---------------------------------------------------------------------------[0m
[0;31mAttributeError[0m                            Traceback (most recent call last)
[0;32m<ipython-input-6-87667bfc3b02>[0m in [0;36m<module>[0;34m[0m
[1;32m      4[0m [0melem_args[0m [0;34m=[0m [0mdict[0m[0;34m([0m[0margs_2[0m[0;34m=[0m[0;34m[[0m[0mdict[0m[0;34m([0m[0matoms[0m[0;34m=[0m[0mlayer[0m[0;34m,[0m [0mm_s[0m[0;34m=[0m[0mm_s[0m[0;34m)[0m [0;32mfor[0m [0mlayer[0m [0;32min[0m [0;34m[[0m[0mlayer_1[0m[0;34m,[0m [0mlayer_2[0m[0;34m][0m [0;32mfor[0m [0mm_s[0m [0;32min[0m [0;34m[[0m[0;34m-[0m[0;36m0.5[0m[0;34m,[0m [0;36m0.5[0m[0;34m][0m[0;34m][0m[0;34m)[0m[0;34m[0m[0;34m[0m[0m
[1;32m      5[0m [0mlegend_tags[0m [0;34m=[0m [0;34m[[0m[0;34m'layer '[0m[0;34m+[0m[0mstr[0m[0;34m([0m[0mi[0m[0;34m)[0m[0;34m+[0m[0;34m' '[0m[0;34m+[0m[0mÏƒ[0m [0;32mfor[0m [0mi[0m [0;32min[0m [0;34m[[0m[0;36m1[0m[0;34m,[0m [0;36m2[0m[0;34m][0m [0;32mfor[0m [0mÏƒ[0m [0;32min[0m [0;34m[[0m[0;34m'â†“'[0m[0;34m,[0m [0;34m'â†‘'[0m[0;34m][0m[0;34m][0m[0;34m[0m[0;34m[0m[0m
[0;32m----> 6[0;31m tb.plot_wfc(
[0m[1;32m      7[0m     [0mdis_min[0m[0;34m=[0m[0;34m-[0m[0;36m5.5[0m[0;34m,[0m[0;34m[0m[0;34m[0m[0m
[1;32m      8[0m     [0mdis_max[0m[0;34m=[0m [0;34m-[0m[0;36m3[0m[0;34m,[0m[0;34m[0m[0;34m[0m[0m

[0;31mAttributeError[0m: 'DFT' object has no attribute 'plot_wfc'
AttributeError: 'DFT' object has no attribute 'plot_wfc'

